#HPF:
#process: 1 arrived at 2
#ReadyQueue has 1 processes
At time 2 process 1 started arr 2 total 10 remain 10 wait 0
#process: 2 arrived at 2
#ReadyQueue has 1 processes
At time 2 process 1 stopped arr 2 total 10 remain 10 wait 0
At time 2 process 2 started arr 2 total 18 remain 18 wait 0
#process: 3 arrived at 10
#ReadyQueue has 2 processes
#process: 4 arrived at 12
#ReadyQueue has 3 processes
#process: 5 arrived at 15
#ReadyQueue has 4 processes
#process: 6 arrived at 18
#ReadyQueue has 5 processes
At time 18 process 2 stopped arr 2 total 18 remain 2 wait 0
At time 18 process 6 started arr 18 total 10 remain 10 wait 0
#process: 7 arrived at 18
#ReadyQueue has 6 processes
#process: 8 arrived at 18
#ReadyQueue has 7 processes
#process: 9 arrived at 28
#ReadyQueue has 8 processes
At time 28 process 6 finished arr 18 total 10 remain 0 wait 0
At time 28 process 2 resumed arr 2 total 18 remain 2 wait 16
At time 30 process 2 finished arr 2 total 18 remain 0 wait 16
At time 30 process 3 started arr 10 total 10 remain 10 wait 20
#process: 10 arrived at 32
#ReadyQueue has 7 processes
#Recieved Termination message.
At time 40 process 3 finished arr 10 total 10 remain 0 wait 20
At time 40 process 7 started arr 18 total 28 remain 28 wait 22
At time 68 process 7 finished arr 18 total 28 remain 0 wait 22
At time 68 process 8 started arr 18 total 12 remain 12 wait 50
At time 80 process 8 finished arr 18 total 12 remain 0 wait 50
At time 80 process 5 started arr 15 total 16 remain 16 wait 65
At time 96 process 5 finished arr 15 total 16 remain 0 wait 65
At time 96 process 9 started arr 28 total 3 remain 3 wait 68
At time 99 process 9 finished arr 28 total 3 remain 0 wait 68
At time 99 process 1 resumed arr 2 total 10 remain 10 wait 0
At time 108 process 1 finished arr 2 total 10 remain 1 wait 0
At time 108 process 10 started arr 32 total 12 remain 12 wait 76
At time 120 process 10 finished arr 32 total 12 remain 0 wait 76
At time 120 process 4 started arr 12 total 9 remain 9 wait 108
At time 129 process 4 finished arr 12 total 9 remain 0 wait 108
#ReadyQueue has 0 processes
